{
 "cells": [
  {
   "cell_type": "markdown",
   "metadata": {
    "deletable": false,
    "editable": false,
    "nbgrader": {
     "grade": false,
     "locked": true,
     "solution": false
    }
   },
   "source": [
    "# Using the error stack trace to debug code"
   ]
  },
  {
   "cell_type": "markdown",
   "metadata": {
    "deletable": false,
    "editable": false,
    "nbgrader": {
     "grade": false,
     "locked": true,
     "solution": false
    }
   },
   "source": [
    "In this course, the test cells often use assert statements to throw errors when the solution is not correct. The error message usually includes something about why the assertion failed, e.g. \"function output is not a dictionary\", \"variable foo is the wrong size\", \"foo does not match the instructor's solution\", etc. These errors usually point you directly towards what needs to be fixed. This type of error is not what this notebook focuses on.\n",
    "\n",
    "Of course, these assertions aren't the only case where code can fail. The Python interpreter will throw errors any time it is unable to do what is asked of it. These error messages, also known as a **traceback**, display where the error was made from the bit of code Python was unable to execute and all of the function calls that lead to that bit of code being attempted. \n",
    "\n",
    "First, let's import numpy and pandas."
   ]
  },
  {
   "cell_type": "code",
   "execution_count": 1,
   "metadata": {
    "collapsed": true,
    "deletable": false,
    "editable": false,
    "nbgrader": {
     "grade": false,
     "locked": true,
     "solution": false
    }
   },
   "outputs": [],
   "source": [
    "import numpy as np\n",
    "import pandas as pd"
   ]
  },
  {
   "cell_type": "markdown",
   "metadata": {
    "deletable": false,
    "editable": false,
    "nbgrader": {
     "grade": false,
     "locked": true,
     "solution": false
    }
   },
   "source": [
    "# Numpy example"
   ]
  },
  {
   "cell_type": "markdown",
   "metadata": {
    "deletable": false,
    "editable": false,
    "nbgrader": {
     "grade": false,
     "locked": true,
     "solution": false
    }
   },
   "source": [
    "Here is a simple example of how the stack trace works. The printsum function is dependent on the add function. "
   ]
  },
  {
   "cell_type": "code",
   "execution_count": 2,
   "metadata": {
    "collapsed": true,
    "deletable": false,
    "editable": false,
    "nbgrader": {
     "grade": false,
     "locked": true,
     "solution": false
    }
   },
   "outputs": [],
   "source": [
    "def printsum(a,b):\n",
    "    # This is\n",
    "    # defined in an undeitable cell\n",
    "    print(add(a,b))\n",
    "    \n",
    "def add(x,y):\n",
    "    # This is\n",
    "    # defined in an uneditable cell\n",
    "    s = x+y\n",
    "    return(s)"
   ]
  },
  {
   "cell_type": "markdown",
   "metadata": {
    "deletable": false,
    "editable": false,
    "nbgrader": {
     "grade": false,
     "locked": true,
     "solution": false
    }
   },
   "source": [
    "The variables \"foo\" and \"bar\" are loaded from a separate file. **For the sake of the example, assume that \"foo\" and \"bar\" were defined in an exercise solution, but the functions were defined in an uneditable block**. The values of bar *should* be the values of foo squared. Let's see if we can add them with **printsum** to get foo+foo\\*\\*2 displayed as output..."
   ]
  },
  {
   "cell_type": "code",
   "execution_count": 3,
   "metadata": {
    "deletable": false,
    "editable": false,
    "nbgrader": {
     "grade": false,
     "locked": true,
     "solution": false
    }
   },
   "outputs": [
    {
     "ename": "ValueError",
     "evalue": "operands could not be broadcast together with shapes (2,4) (4,2) ",
     "output_type": "error",
     "traceback": [
      "\u001b[0;31m---------------------------------------------------------------------------\u001b[0m",
      "\u001b[0;31mValueError\u001b[0m                                Traceback (most recent call last)",
      "\u001b[0;32m<ipython-input-3-8acac145d801>\u001b[0m in \u001b[0;36m<module>\u001b[0;34m()\u001b[0m\n\u001b[1;32m      1\u001b[0m \u001b[0;32mfrom\u001b[0m \u001b[0mfoobar\u001b[0m \u001b[0;32mimport\u001b[0m \u001b[0mfoo\u001b[0m\u001b[0;34m,\u001b[0m \u001b[0mbar\u001b[0m\u001b[0;34m\u001b[0m\u001b[0m\n\u001b[0;32m----> 2\u001b[0;31m \u001b[0mprintsum\u001b[0m\u001b[0;34m(\u001b[0m\u001b[0mfoo\u001b[0m\u001b[0;34m,\u001b[0m \u001b[0mbar\u001b[0m\u001b[0;34m)\u001b[0m\u001b[0;34m\u001b[0m\u001b[0m\n\u001b[0m",
      "\u001b[0;32m<ipython-input-2-e1f2e49ec6b7>\u001b[0m in \u001b[0;36mprintsum\u001b[0;34m(a, b)\u001b[0m\n\u001b[1;32m      2\u001b[0m     \u001b[0;31m# This is\u001b[0m\u001b[0;34m\u001b[0m\u001b[0;34m\u001b[0m\u001b[0m\n\u001b[1;32m      3\u001b[0m     \u001b[0;31m# defined in an undeitable cell\u001b[0m\u001b[0;34m\u001b[0m\u001b[0;34m\u001b[0m\u001b[0m\n\u001b[0;32m----> 4\u001b[0;31m     \u001b[0mprint\u001b[0m\u001b[0;34m(\u001b[0m\u001b[0madd\u001b[0m\u001b[0;34m(\u001b[0m\u001b[0ma\u001b[0m\u001b[0;34m,\u001b[0m\u001b[0mb\u001b[0m\u001b[0;34m)\u001b[0m\u001b[0;34m)\u001b[0m\u001b[0;34m\u001b[0m\u001b[0m\n\u001b[0m\u001b[1;32m      5\u001b[0m \u001b[0;34m\u001b[0m\u001b[0m\n\u001b[1;32m      6\u001b[0m \u001b[0;32mdef\u001b[0m \u001b[0madd\u001b[0m\u001b[0;34m(\u001b[0m\u001b[0mx\u001b[0m\u001b[0;34m,\u001b[0m\u001b[0my\u001b[0m\u001b[0;34m)\u001b[0m\u001b[0;34m:\u001b[0m\u001b[0;34m\u001b[0m\u001b[0m\n",
      "\u001b[0;32m<ipython-input-2-e1f2e49ec6b7>\u001b[0m in \u001b[0;36madd\u001b[0;34m(x, y)\u001b[0m\n\u001b[1;32m      7\u001b[0m     \u001b[0;31m# This is\u001b[0m\u001b[0;34m\u001b[0m\u001b[0;34m\u001b[0m\u001b[0m\n\u001b[1;32m      8\u001b[0m     \u001b[0;31m# defined in an uneditable cell\u001b[0m\u001b[0;34m\u001b[0m\u001b[0;34m\u001b[0m\u001b[0m\n\u001b[0;32m----> 9\u001b[0;31m     \u001b[0ms\u001b[0m \u001b[0;34m=\u001b[0m \u001b[0mx\u001b[0m\u001b[0;34m+\u001b[0m\u001b[0my\u001b[0m\u001b[0;34m\u001b[0m\u001b[0m\n\u001b[0m\u001b[1;32m     10\u001b[0m     \u001b[0;32mreturn\u001b[0m\u001b[0;34m(\u001b[0m\u001b[0ms\u001b[0m\u001b[0;34m)\u001b[0m\u001b[0;34m\u001b[0m\u001b[0m\n",
      "\u001b[0;31mValueError\u001b[0m: operands could not be broadcast together with shapes (2,4) (4,2) "
     ]
    }
   ],
   "source": [
    "from foobar import foo, bar\n",
    "printsum(foo, bar)"
   ]
  },
  {
   "cell_type": "markdown",
   "metadata": {
    "deletable": false,
    "editable": false,
    "nbgrader": {
     "grade": false,
     "locked": true,
     "solution": false
    }
   },
   "source": [
    "Oh, no! It didn't work. The bottom of the stack trace shows that x and y couldn't be broadcast together. \"I never did anything with x or y, there must be a problem with the notebook!\" might be the first thought to come to mind. However, examining the whole traceback shows something different. The problem started with the call to **printsum** and pertains to the **shape of two arrays**. The natural next step is to look at the shapes of the arrays fed into **printsum** and possibly the variables themselves."
   ]
  },
  {
   "cell_type": "code",
   "execution_count": 4,
   "metadata": {
    "deletable": false,
    "editable": false,
    "nbgrader": {
     "grade": false,
     "locked": true,
     "solution": false
    }
   },
   "outputs": [
    {
     "name": "stdout",
     "output_type": "stream",
     "text": [
      "foo's shape: (2, 4)\n",
      "[[1 2 3 4]\n",
      " [5 6 7 8]]\n",
      "bar's shape: (4, 2)\n",
      "[[ 1 25]\n",
      " [ 4 36]\n",
      " [ 9 49]\n",
      " [16 64]]\n"
     ]
    }
   ],
   "source": [
    "print('foo\\'s shape:', foo.shape)\n",
    "print(foo)\n",
    "print('bar\\'s shape:', bar.shape)\n",
    "print(bar)"
   ]
  },
  {
   "cell_type": "markdown",
   "metadata": {
    "deletable": false,
    "editable": false,
    "nbgrader": {
     "grade": false,
     "locked": true,
     "solution": false
    }
   },
   "source": [
    "The bar array somehow got transposed, but the numbers are correct. The real way to resolve this issue is to find the root cause wherever bar is defined, but since that only exists hypothetically, let's correct it here by modifying the call to **printsum**."
   ]
  },
  {
   "cell_type": "code",
   "execution_count": 5,
   "metadata": {
    "deletable": false,
    "editable": false,
    "nbgrader": {
     "grade": false,
     "locked": true,
     "solution": false
    }
   },
   "outputs": [
    {
     "name": "stdout",
     "output_type": "stream",
     "text": [
      "[[ 2  6 12 20]\n",
      " [30 42 56 72]]\n"
     ]
    }
   ],
   "source": [
    "printsum(foo, bar.T)"
   ]
  },
  {
   "cell_type": "markdown",
   "metadata": {
    "deletable": false,
    "editable": false,
    "nbgrader": {
     "grade": false,
     "locked": true,
     "solution": false
    }
   },
   "source": [
    "Some common numpy errors are broadcasting and type errors (recall everything in an array has to be of the same type). These basic errors might rear their ugly heads when calling functions that take array inputs. The bottom of the stack trace will have some lines of code that aren't even in the notebook. This is OK. Use the error message to **find where code that you wrote** may have caused the problem. "
   ]
  },
  {
   "cell_type": "markdown",
   "metadata": {
    "deletable": false,
    "editable": false,
    "nbgrader": {
     "grade": false,
     "locked": true,
     "solution": false
    }
   },
   "source": [
    "# Pandas example"
   ]
  },
  {
   "cell_type": "markdown",
   "metadata": {
    "deletable": false,
    "editable": false,
    "nbgrader": {
     "grade": false,
     "locked": true,
     "solution": false
    }
   },
   "source": [
    "Basic pandas errors are also often thrown as a result of function calls on dataframes that aren't as expected. The stack trace is useful to figure out where the issue is in these cases as well. Some common errors are index errors, using the wrong version of loc/iloc, and problems with grouping or merging."
   ]
  },
  {
   "cell_type": "markdown",
   "metadata": {
    "deletable": false,
    "editable": false,
    "nbgrader": {
     "grade": false,
     "locked": true,
     "solution": false
    }
   },
   "source": [
    "For this example suppose that you have to write a function that vertically stacks some data frames. The column 'baz' **may** be named 'BAZ' in **some** of the inputs, and you are required to handle this and the returned data frame must have all 'baz'."
   ]
  },
  {
   "cell_type": "code",
   "execution_count": 6,
   "metadata": {
    "collapsed": true,
    "deletable": false,
    "editable": false,
    "nbgrader": {
     "grade": false,
     "locked": true,
     "solution": false
    }
   },
   "outputs": [],
   "source": [
    "from foobar import df_foo, df_bar"
   ]
  },
  {
   "cell_type": "code",
   "execution_count": 7,
   "metadata": {
    "deletable": false,
    "editable": false,
    "nbgrader": {
     "grade": false,
     "locked": true,
     "solution": false
    }
   },
   "outputs": [
    {
     "name": "stdout",
     "output_type": "stream",
     "text": [
      "   baz  bop\n",
      "0  1.0   11\n",
      "1  2.0   12\n",
      "2  3.0   13\n",
      "3  4.0   14\n",
      "0  1.0   11\n",
      "1  2.0   12\n",
      "2  3.0   13\n",
      "3  4.0   14\n"
     ]
    },
    {
     "name": "stderr",
     "output_type": "stream",
     "text": [
      "/usr/local/lib/python3.6/site-packages/ipykernel_launcher.py:3: FutureWarning: Sorting because non-concatenation axis is not aligned. A future version\n",
      "of pandas will change to not sort by default.\n",
      "\n",
      "To accept the future behavior, pass 'sort=False'.\n",
      "\n",
      "To retain the current behavior and silence the warning, pass 'sort=True'.\n",
      "\n",
      "  This is separate from the ipykernel package so we can avoid doing imports until\n"
     ]
    }
   ],
   "source": [
    "def df_stack(dfs):\n",
    "    # concatenate the dataframes in dfs.\n",
    "    df_foobar = pd.concat(dfs, axis=0).fillna(0)\n",
    "    # Add the columns named BAZ and baz together (remember NA were set to zero)\n",
    "    baz_se = df_foobar.BAZ + df_foobar.baz\n",
    "    # Drop the column with the wrong name\n",
    "    df_foobar.drop('BAZ',axis=1, inplace=True)\n",
    "    # Assign the baz values to the baz column\n",
    "    df_foobar[['baz']] = baz_se\n",
    "    return(df_foobar)\n",
    "\n",
    "print(df_stack([df_foo, df_bar]))"
   ]
  },
  {
   "cell_type": "markdown",
   "metadata": {
    "deletable": false,
    "editable": false,
    "nbgrader": {
     "grade": false,
     "locked": true,
     "solution": false
    }
   },
   "source": [
    "Our funciton df_stack appears to work correctly. The test cells will often check \"edge cases\" which may reveal that the function isn't able to handle specific types of inputs that it should be able to. "
   ]
  },
  {
   "cell_type": "code",
   "execution_count": 8,
   "metadata": {
    "deletable": false,
    "editable": false,
    "nbgrader": {
     "grade": false,
     "locked": true,
     "solution": false
    }
   },
   "outputs": [
    {
     "name": "stderr",
     "output_type": "stream",
     "text": [
      "ERROR:root:Internal Python error in the inspect module.\n",
      "Below is the traceback from this internal error.\n",
      "\n"
     ]
    },
    {
     "name": "stdout",
     "output_type": "stream",
     "text": [
      "Traceback (most recent call last):\n",
      "  File \"/usr/local/lib/python3.6/site-packages/IPython/core/interactiveshell.py\", line 2961, in run_code\n",
      "    exec(code_obj, self.user_global_ns, self.user_ns)\n",
      "  File \"<ipython-input-8-c231723a095d>\", line 5, in <module>\n",
      "    df = df_stack([df_foo, df_test])\n",
      "  File \"<ipython-input-7-9c441f17ddee>\", line 5, in df_stack\n",
      "    baz_se = df_foobar.BAZ + df_foobar.baz\n",
      "  File \"/usr/local/lib/python3.6/site-packages/pandas/core/generic.py\", line 4376, in __getattr__\n",
      "    return object.__getattribute__(self, name)\n",
      "AttributeError: 'DataFrame' object has no attribute 'BAZ'\n",
      "\n",
      "During handling of the above exception, another exception occurred:\n",
      "\n",
      "Traceback (most recent call last):\n",
      "  File \"/usr/local/lib/python3.6/site-packages/IPython/core/interactiveshell.py\", line 1863, in showtraceback\n",
      "    stb = value._render_traceback_()\n",
      "AttributeError: 'AttributeError' object has no attribute '_render_traceback_'\n",
      "\n",
      "During handling of the above exception, another exception occurred:\n",
      "\n",
      "Traceback (most recent call last):\n",
      "  File \"/usr/local/lib/python3.6/site-packages/IPython/core/ultratb.py\", line 1095, in get_records\n",
      "    return _fixed_getinnerframes(etb, number_of_lines_of_context, tb_offset)\n",
      "  File \"/usr/local/lib/python3.6/site-packages/IPython/core/ultratb.py\", line 311, in wrapped\n",
      "    return f(*args, **kwargs)\n",
      "  File \"/usr/local/lib/python3.6/site-packages/IPython/core/ultratb.py\", line 345, in _fixed_getinnerframes\n",
      "    records = fix_frame_records_filenames(inspect.getinnerframes(etb, context))\n",
      "  File \"/usr/local/lib/python3.6/inspect.py\", line 1483, in getinnerframes\n",
      "    frameinfo = (tb.tb_frame,) + getframeinfo(tb, context)\n",
      "  File \"/usr/local/lib/python3.6/inspect.py\", line 1441, in getframeinfo\n",
      "    filename = getsourcefile(frame) or getfile(frame)\n",
      "  File \"/usr/local/lib/python3.6/inspect.py\", line 696, in getsourcefile\n",
      "    if getattr(getmodule(object, filename), '__loader__', None) is not None:\n",
      "  File \"/usr/local/lib/python3.6/inspect.py\", line 733, in getmodule\n",
      "    if ismodule(module) and hasattr(module, '__file__'):\n",
      "  File \"/usr/local/lib/python3.6/site-packages/py/_vendored_packages/apipkg.py\", line 195, in __getattribute__\n",
      "    return getattr(getmod(), name)\n",
      "  File \"/usr/local/lib/python3.6/site-packages/py/_vendored_packages/apipkg.py\", line 179, in getmod\n",
      "    x = importobj(modpath, None)\n",
      "  File \"/usr/local/lib/python3.6/site-packages/py/_vendored_packages/apipkg.py\", line 69, in importobj\n",
      "    module = __import__(modpath, None, None, ['__doc__'])\n",
      "  File \"/usr/local/lib/python3.6/site-packages/pytest.py\", line 13, in <module>\n",
      "    from _pytest.fixtures import fixture, yield_fixture\n",
      "  File \"/usr/local/lib/python3.6/site-packages/_pytest/fixtures.py\", line 832, in <module>\n",
      "    class FixtureFunctionMarker(object):\n",
      "  File \"/usr/local/lib/python3.6/site-packages/_pytest/fixtures.py\", line 834, in FixtureFunctionMarker\n",
      "    params = attr.ib(convert=attr.converters.optional(tuple))\n",
      "TypeError: attrib() got an unexpected keyword argument 'convert'\n"
     ]
    },
    {
     "ename": "AttributeError",
     "evalue": "'DataFrame' object has no attribute 'BAZ'",
     "output_type": "error",
     "traceback": [
      "\u001b[0;31m---------------------------------------------------------------------------\u001b[0m"
     ]
    }
   ],
   "source": [
    "from foobar import df_test\n",
    "# some other code\n",
    "#\n",
    "#\n",
    "df = df_stack([df_foo, df_test])\n",
    "# some more code\n",
    "#\n",
    "#"
   ]
  },
  {
   "cell_type": "markdown",
   "metadata": {
    "deletable": false,
    "editable": false,
    "nbgrader": {
     "grade": false,
     "locked": true,
     "solution": false
    }
   },
   "source": [
    "The function didn't work this time, even though the demo worked. Examining the traceback reveals that the call to **df_stack** was the origin of the error. This call led to the \"baz_se = ...\" line being attempted. That line resulted to a call to the pandas library that was unable to be executed. There appears to be an issue with the column names in **df_stack**. We can investigate further by looking at the column headers for each data frame in the list dfs. \n",
    "\n",
    "Note: the debugging is done in a separate cell for demonstration purposes, but on an assignment, you would want to add this code to your original function definition.\n",
    "\n",
    "Additional note: because the function call threw an error, the variable df never gets assigned. If an attempt to use it is made in subsequent cells, more errors will result. See below"
   ]
  },
  {
   "cell_type": "code",
   "execution_count": 9,
   "metadata": {
    "deletable": false,
    "editable": false,
    "nbgrader": {
     "grade": false,
     "locked": true,
     "solution": false
    }
   },
   "outputs": [
    {
     "name": "stderr",
     "output_type": "stream",
     "text": [
      "ERROR:root:Internal Python error in the inspect module.\n",
      "Below is the traceback from this internal error.\n",
      "\n"
     ]
    },
    {
     "name": "stdout",
     "output_type": "stream",
     "text": [
      "Traceback (most recent call last):\n",
      "  File \"/usr/local/lib/python3.6/site-packages/IPython/core/interactiveshell.py\", line 2961, in run_code\n",
      "    exec(code_obj, self.user_global_ns, self.user_ns)\n",
      "  File \"<ipython-input-9-2a851eda2e88>\", line 1, in <module>\n",
      "    print(df)\n",
      "NameError: name 'df' is not defined\n",
      "\n",
      "During handling of the above exception, another exception occurred:\n",
      "\n",
      "Traceback (most recent call last):\n",
      "  File \"/usr/local/lib/python3.6/site-packages/IPython/core/interactiveshell.py\", line 1863, in showtraceback\n",
      "    stb = value._render_traceback_()\n",
      "AttributeError: 'NameError' object has no attribute '_render_traceback_'\n",
      "\n",
      "During handling of the above exception, another exception occurred:\n",
      "\n",
      "Traceback (most recent call last):\n",
      "  File \"/usr/local/lib/python3.6/site-packages/IPython/core/ultratb.py\", line 1095, in get_records\n",
      "    return _fixed_getinnerframes(etb, number_of_lines_of_context, tb_offset)\n",
      "  File \"/usr/local/lib/python3.6/site-packages/IPython/core/ultratb.py\", line 311, in wrapped\n",
      "    return f(*args, **kwargs)\n",
      "  File \"/usr/local/lib/python3.6/site-packages/IPython/core/ultratb.py\", line 345, in _fixed_getinnerframes\n",
      "    records = fix_frame_records_filenames(inspect.getinnerframes(etb, context))\n",
      "  File \"/usr/local/lib/python3.6/inspect.py\", line 1483, in getinnerframes\n",
      "    frameinfo = (tb.tb_frame,) + getframeinfo(tb, context)\n",
      "  File \"/usr/local/lib/python3.6/inspect.py\", line 1441, in getframeinfo\n",
      "    filename = getsourcefile(frame) or getfile(frame)\n",
      "  File \"/usr/local/lib/python3.6/inspect.py\", line 696, in getsourcefile\n",
      "    if getattr(getmodule(object, filename), '__loader__', None) is not None:\n",
      "  File \"/usr/local/lib/python3.6/inspect.py\", line 733, in getmodule\n",
      "    if ismodule(module) and hasattr(module, '__file__'):\n",
      "  File \"/usr/local/lib/python3.6/site-packages/py/_vendored_packages/apipkg.py\", line 195, in __getattribute__\n",
      "    return getattr(getmod(), name)\n",
      "  File \"/usr/local/lib/python3.6/site-packages/py/_vendored_packages/apipkg.py\", line 179, in getmod\n",
      "    x = importobj(modpath, None)\n",
      "  File \"/usr/local/lib/python3.6/site-packages/py/_vendored_packages/apipkg.py\", line 69, in importobj\n",
      "    module = __import__(modpath, None, None, ['__doc__'])\n",
      "  File \"/usr/local/lib/python3.6/site-packages/pytest.py\", line 13, in <module>\n",
      "    from _pytest.fixtures import fixture, yield_fixture\n",
      "  File \"/usr/local/lib/python3.6/site-packages/_pytest/fixtures.py\", line 832, in <module>\n",
      "    class FixtureFunctionMarker(object):\n",
      "  File \"/usr/local/lib/python3.6/site-packages/_pytest/fixtures.py\", line 834, in FixtureFunctionMarker\n",
      "    params = attr.ib(convert=attr.converters.optional(tuple))\n",
      "TypeError: attrib() got an unexpected keyword argument 'convert'\n"
     ]
    },
    {
     "ename": "NameError",
     "evalue": "name 'df' is not defined",
     "output_type": "error",
     "traceback": [
      "\u001b[0;31m---------------------------------------------------------------------------\u001b[0m"
     ]
    }
   ],
   "source": [
    "print(df)"
   ]
  },
  {
   "cell_type": "markdown",
   "metadata": {
    "deletable": false,
    "editable": false,
    "nbgrader": {
     "grade": false,
     "locked": true,
     "solution": false
    }
   },
   "source": [
    "This can be confusing, especially if the assignment is made in an uneditable cell or the name df is used in multiple namespaces. The find function in your browser (ctrl+F) can be helpful in figuring out where df should have been assigned but wasn't. Now on to the debugging. Remember we have an issue with the columns of the dataframes in dfs, so let's print them. "
   ]
  },
  {
   "cell_type": "code",
   "execution_count": 10,
   "metadata": {
    "deletable": false,
    "editable": false,
    "nbgrader": {
     "grade": false,
     "locked": true,
     "solution": false
    }
   },
   "outputs": [
    {
     "name": "stdout",
     "output_type": "stream",
     "text": [
      "Index(['baz', 'bop'], dtype='object')\n",
      "Index(['BAZ', 'bop'], dtype='object')\n",
      "   baz  bop\n",
      "0  1.0   11\n",
      "1  2.0   12\n",
      "2  3.0   13\n",
      "3  4.0   14\n",
      "0  1.0   11\n",
      "1  2.0   12\n",
      "2  3.0   13\n",
      "3  4.0   14\n"
     ]
    },
    {
     "name": "stderr",
     "output_type": "stream",
     "text": [
      "/usr/local/lib/python3.6/site-packages/ipykernel_launcher.py:6: FutureWarning: Sorting because non-concatenation axis is not aligned. A future version\n",
      "of pandas will change to not sort by default.\n",
      "\n",
      "To accept the future behavior, pass 'sort=False'.\n",
      "\n",
      "To retain the current behavior and silence the warning, pass 'sort=True'.\n",
      "\n",
      "  \n"
     ]
    }
   ],
   "source": [
    "def df_stack(dfs):\n",
    "    # begin debug code\n",
    "    for df in dfs:\n",
    "        print(df.columns)\n",
    "    # end debug code\n",
    "    df_foobar = pd.concat(dfs, axis=0).fillna(0)\n",
    "    baz_se = df_foobar.BAZ + df_foobar.baz\n",
    "    df_foobar.drop('BAZ',axis=1, inplace=True)\n",
    "    df_foobar[['baz']] = baz_se\n",
    "    return(df_foobar)\n",
    "\n",
    "print(df_stack([df_foo, df_bar]))"
   ]
  },
  {
   "cell_type": "markdown",
   "metadata": {
    "deletable": false,
    "editable": false,
    "nbgrader": {
     "grade": false,
     "locked": true,
     "solution": false
    }
   },
   "source": [
    "The demo still works with the print statement. Let's try the test again."
   ]
  },
  {
   "cell_type": "code",
   "execution_count": 11,
   "metadata": {
    "deletable": false,
    "editable": false,
    "nbgrader": {
     "grade": false,
     "locked": true,
     "solution": false
    }
   },
   "outputs": [
    {
     "name": "stderr",
     "output_type": "stream",
     "text": [
      "ERROR:root:Internal Python error in the inspect module.\n",
      "Below is the traceback from this internal error.\n",
      "\n"
     ]
    },
    {
     "name": "stdout",
     "output_type": "stream",
     "text": [
      "Index(['baz', 'bop'], dtype='object')\n",
      "Index(['baz', 'bop'], dtype='object')\n",
      "Traceback (most recent call last):\n",
      "  File \"/usr/local/lib/python3.6/site-packages/IPython/core/interactiveshell.py\", line 2961, in run_code\n",
      "    exec(code_obj, self.user_global_ns, self.user_ns)\n",
      "  File \"<ipython-input-11-241e5153d046>\", line 1, in <module>\n",
      "    df = df_stack([df_foo, df_test])\n",
      "  File \"<ipython-input-10-6b08d54c65f8>\", line 7, in df_stack\n",
      "    baz_se = df_foobar.BAZ + df_foobar.baz\n",
      "  File \"/usr/local/lib/python3.6/site-packages/pandas/core/generic.py\", line 4376, in __getattr__\n",
      "    return object.__getattribute__(self, name)\n",
      "AttributeError: 'DataFrame' object has no attribute 'BAZ'\n",
      "\n",
      "During handling of the above exception, another exception occurred:\n",
      "\n",
      "Traceback (most recent call last):\n",
      "  File \"/usr/local/lib/python3.6/site-packages/IPython/core/interactiveshell.py\", line 1863, in showtraceback\n",
      "    stb = value._render_traceback_()\n",
      "AttributeError: 'AttributeError' object has no attribute '_render_traceback_'\n",
      "\n",
      "During handling of the above exception, another exception occurred:\n",
      "\n",
      "Traceback (most recent call last):\n",
      "  File \"/usr/local/lib/python3.6/site-packages/IPython/core/ultratb.py\", line 1095, in get_records\n",
      "    return _fixed_getinnerframes(etb, number_of_lines_of_context, tb_offset)\n",
      "  File \"/usr/local/lib/python3.6/site-packages/IPython/core/ultratb.py\", line 311, in wrapped\n",
      "    return f(*args, **kwargs)\n",
      "  File \"/usr/local/lib/python3.6/site-packages/IPython/core/ultratb.py\", line 345, in _fixed_getinnerframes\n",
      "    records = fix_frame_records_filenames(inspect.getinnerframes(etb, context))\n",
      "  File \"/usr/local/lib/python3.6/inspect.py\", line 1483, in getinnerframes\n",
      "    frameinfo = (tb.tb_frame,) + getframeinfo(tb, context)\n",
      "  File \"/usr/local/lib/python3.6/inspect.py\", line 1441, in getframeinfo\n",
      "    filename = getsourcefile(frame) or getfile(frame)\n",
      "  File \"/usr/local/lib/python3.6/inspect.py\", line 696, in getsourcefile\n",
      "    if getattr(getmodule(object, filename), '__loader__', None) is not None:\n",
      "  File \"/usr/local/lib/python3.6/inspect.py\", line 733, in getmodule\n",
      "    if ismodule(module) and hasattr(module, '__file__'):\n",
      "  File \"/usr/local/lib/python3.6/site-packages/py/_vendored_packages/apipkg.py\", line 195, in __getattribute__\n",
      "    return getattr(getmod(), name)\n",
      "  File \"/usr/local/lib/python3.6/site-packages/py/_vendored_packages/apipkg.py\", line 179, in getmod\n",
      "    x = importobj(modpath, None)\n",
      "  File \"/usr/local/lib/python3.6/site-packages/py/_vendored_packages/apipkg.py\", line 69, in importobj\n",
      "    module = __import__(modpath, None, None, ['__doc__'])\n",
      "  File \"/usr/local/lib/python3.6/site-packages/pytest.py\", line 13, in <module>\n",
      "    from _pytest.fixtures import fixture, yield_fixture\n",
      "  File \"/usr/local/lib/python3.6/site-packages/_pytest/fixtures.py\", line 832, in <module>\n",
      "    class FixtureFunctionMarker(object):\n",
      "  File \"/usr/local/lib/python3.6/site-packages/_pytest/fixtures.py\", line 834, in FixtureFunctionMarker\n",
      "    params = attr.ib(convert=attr.converters.optional(tuple))\n",
      "TypeError: attrib() got an unexpected keyword argument 'convert'\n"
     ]
    },
    {
     "ename": "AttributeError",
     "evalue": "'DataFrame' object has no attribute 'BAZ'",
     "output_type": "error",
     "traceback": [
      "\u001b[0;31m---------------------------------------------------------------------------\u001b[0m"
     ]
    }
   ],
   "source": [
    "df = df_stack([df_foo, df_test])"
   ]
  },
  {
   "cell_type": "markdown",
   "metadata": {
    "deletable": false,
    "editable": false,
    "nbgrader": {
     "grade": false,
     "locked": true,
     "solution": false
    }
   },
   "source": [
    "We got the same error traceback, but this time we are armed with more information. The test list didn't have any columns named \"BAZ\"! By directly referencing the column, we require it to exist. Another logical conclusion is if **none** of the baz columns in dfs are named \"baz\" our code will also throw an error.\n",
    "\n",
    "Somehow we need to change the names of the columns named \"BAZ\" to \"baz\" **without requiring that either name exists** (only one or the other), and this should probably be done before the concatenation."
   ]
  },
  {
   "cell_type": "code",
   "execution_count": 12,
   "metadata": {
    "deletable": false,
    "editable": false,
    "nbgrader": {
     "grade": false,
     "locked": true,
     "solution": false
    }
   },
   "outputs": [
    {
     "name": "stdout",
     "output_type": "stream",
     "text": [
      "Index(['baz', 'bop'], dtype='object')\n",
      "Index(['BAZ', 'bop'], dtype='object')\n",
      "   baz  bop\n",
      "0    1   11\n",
      "1    2   12\n",
      "2    3   13\n",
      "3    4   14\n",
      "0    1   11\n",
      "1    2   12\n",
      "2    3   13\n",
      "3    4   14\n"
     ]
    }
   ],
   "source": [
    "def df_stack(dfs):\n",
    "    # begin debug code\n",
    "    for df in dfs:\n",
    "        print(df.columns)\n",
    "    # end debug code\n",
    "    \n",
    "#     Old implementation\n",
    "\n",
    "#     df_foobar = pd.concat(dfs, axis=0).fillna(0)\n",
    "#     baz_se = df_foobar.BAZ + df_foobar.baz\n",
    "#     df_foobar.drop('BAZ',axis=1, inplace=True)\n",
    "#     df_foobar[['baz']] = baz_se\n",
    "    dfs_new = [df.rename(columns = {'BAZ' : 'baz'})for df in dfs]\n",
    "    df_foobar = pd.concat(dfs_new)\n",
    "    return(df_foobar)\n",
    "\n",
    "print(df_stack([df_foo, df_bar]))"
   ]
  },
  {
   "cell_type": "code",
   "execution_count": 13,
   "metadata": {
    "deletable": false,
    "editable": false,
    "nbgrader": {
     "grade": false,
     "locked": true,
     "solution": false
    }
   },
   "outputs": [
    {
     "name": "stdout",
     "output_type": "stream",
     "text": [
      "Index(['baz', 'bop'], dtype='object')\n",
      "Index(['baz', 'bop'], dtype='object')\n"
     ]
    }
   ],
   "source": [
    "df = df_stack([df_foo, df_test])"
   ]
  },
  {
   "cell_type": "code",
   "execution_count": 14,
   "metadata": {
    "deletable": false,
    "editable": false,
    "nbgrader": {
     "grade": false,
     "locked": true,
     "solution": false
    }
   },
   "outputs": [
    {
     "name": "stdout",
     "output_type": "stream",
     "text": [
      "   baz  bop\n",
      "0    1   11\n",
      "1    2   12\n",
      "2    3   13\n",
      "3    4   14\n",
      "0    1   11\n",
      "1    2   12\n",
      "2    3   13\n",
      "3    4   14\n"
     ]
    }
   ],
   "source": [
    "print(df)"
   ]
  },
  {
   "cell_type": "markdown",
   "metadata": {
    "deletable": false,
    "editable": false,
    "nbgrader": {
     "grade": false,
     "locked": true,
     "solution": false
    }
   },
   "source": [
    "The solution above uses the pd.rename function to handle the naming issue. This function checks the column names for any of the keys in the dictionary. If the key is found, the column name is changed in the output, but the key **is not required to be used**. "
   ]
  },
  {
   "cell_type": "markdown",
   "metadata": {
    "deletable": false,
    "editable": false,
    "nbgrader": {
     "grade": false,
     "locked": true,
     "solution": false
    }
   },
   "source": [
    "# One frustrating type of assertion error"
   ]
  },
  {
   "cell_type": "markdown",
   "metadata": {
    "deletable": false,
    "editable": false,
    "nbgrader": {
     "grade": false,
     "locked": true,
     "solution": false
    }
   },
   "source": [
    "I know we said assertion errors weren't going to be the focus of this notebook, but one case is worth looking into. Suppose a function defined in an exercise solution returns a large collection of outputs called stu_arr, and the instructor's solution called ins_arr. "
   ]
  },
  {
   "cell_type": "code",
   "execution_count": 15,
   "metadata": {
    "deletable": false,
    "editable": false,
    "nbgrader": {
     "grade": false,
     "locked": true,
     "solution": false
    }
   },
   "outputs": [
    {
     "name": "stderr",
     "output_type": "stream",
     "text": [
      "ERROR:root:Internal Python error in the inspect module.\n",
      "Below is the traceback from this internal error.\n",
      "\n"
     ]
    },
    {
     "name": "stdout",
     "output_type": "stream",
     "text": [
      "Traceback (most recent call last):\n",
      "  File \"/usr/local/lib/python3.6/site-packages/IPython/core/interactiveshell.py\", line 2961, in run_code\n",
      "    exec(code_obj, self.user_global_ns, self.user_ns)\n",
      "  File \"<ipython-input-15-4c0c3abd08ff>\", line 3, in <module>\n",
      "    assert (stu_arr == ins_arr).all(), \"Student list did not match instructor list\"\n",
      "AssertionError: Student list did not match instructor list\n",
      "\n",
      "During handling of the above exception, another exception occurred:\n",
      "\n",
      "Traceback (most recent call last):\n",
      "  File \"/usr/local/lib/python3.6/site-packages/IPython/core/interactiveshell.py\", line 1863, in showtraceback\n",
      "    stb = value._render_traceback_()\n",
      "AttributeError: 'AssertionError' object has no attribute '_render_traceback_'\n",
      "\n",
      "During handling of the above exception, another exception occurred:\n",
      "\n",
      "Traceback (most recent call last):\n",
      "  File \"/usr/local/lib/python3.6/site-packages/IPython/core/ultratb.py\", line 1095, in get_records\n",
      "    return _fixed_getinnerframes(etb, number_of_lines_of_context, tb_offset)\n",
      "  File \"/usr/local/lib/python3.6/site-packages/IPython/core/ultratb.py\", line 311, in wrapped\n",
      "    return f(*args, **kwargs)\n",
      "  File \"/usr/local/lib/python3.6/site-packages/IPython/core/ultratb.py\", line 345, in _fixed_getinnerframes\n",
      "    records = fix_frame_records_filenames(inspect.getinnerframes(etb, context))\n",
      "  File \"/usr/local/lib/python3.6/inspect.py\", line 1483, in getinnerframes\n",
      "    frameinfo = (tb.tb_frame,) + getframeinfo(tb, context)\n",
      "  File \"/usr/local/lib/python3.6/inspect.py\", line 1441, in getframeinfo\n",
      "    filename = getsourcefile(frame) or getfile(frame)\n",
      "  File \"/usr/local/lib/python3.6/inspect.py\", line 696, in getsourcefile\n",
      "    if getattr(getmodule(object, filename), '__loader__', None) is not None:\n",
      "  File \"/usr/local/lib/python3.6/inspect.py\", line 733, in getmodule\n",
      "    if ismodule(module) and hasattr(module, '__file__'):\n",
      "  File \"/usr/local/lib/python3.6/site-packages/py/_vendored_packages/apipkg.py\", line 195, in __getattribute__\n",
      "    return getattr(getmod(), name)\n",
      "  File \"/usr/local/lib/python3.6/site-packages/py/_vendored_packages/apipkg.py\", line 179, in getmod\n",
      "    x = importobj(modpath, None)\n",
      "  File \"/usr/local/lib/python3.6/site-packages/py/_vendored_packages/apipkg.py\", line 69, in importobj\n",
      "    module = __import__(modpath, None, None, ['__doc__'])\n",
      "  File \"/usr/local/lib/python3.6/site-packages/pytest.py\", line 13, in <module>\n",
      "    from _pytest.fixtures import fixture, yield_fixture\n",
      "  File \"/usr/local/lib/python3.6/site-packages/_pytest/fixtures.py\", line 832, in <module>\n",
      "    class FixtureFunctionMarker(object):\n",
      "  File \"/usr/local/lib/python3.6/site-packages/_pytest/fixtures.py\", line 834, in FixtureFunctionMarker\n",
      "    params = attr.ib(convert=attr.converters.optional(tuple))\n",
      "TypeError: attrib() got an unexpected keyword argument 'convert'\n"
     ]
    },
    {
     "ename": "AssertionError",
     "evalue": "Student list did not match instructor list",
     "output_type": "error",
     "traceback": [
      "\u001b[0;31m---------------------------------------------------------------------------\u001b[0m"
     ]
    }
   ],
   "source": [
    "from foobar import stu_arr, ins_arr\n",
    "assert stu_arr.shape == ins_arr.shape, \"Student array has incorrect shape\"\n",
    "assert (stu_arr == ins_arr).all(), \"Student list did not match instructor list\""
   ]
  },
  {
   "cell_type": "markdown",
   "metadata": {
    "deletable": false,
    "editable": false,
    "nbgrader": {
     "grade": false,
     "locked": true,
     "solution": false
    }
   },
   "source": [
    "Ok, somewhere our function runs but doesn't compute the correct value. The next step is to find out where. Let's try printing the right answer, the generated answer, and a conditional array that checks for matches..."
   ]
  },
  {
   "cell_type": "code",
   "execution_count": 16,
   "metadata": {
    "deletable": false,
    "editable": false,
    "nbgrader": {
     "grade": false,
     "locked": true,
     "solution": false
    }
   },
   "outputs": [
    {
     "name": "stdout",
     "output_type": "stream",
     "text": [
      "[1. 1. 1. ... 1. 1. 1.]\n",
      "[1. 1. 1. ... 1. 1. 1.]\n",
      "[ True  True  True ...  True  True  True]\n"
     ]
    }
   ],
   "source": [
    "print(stu_arr)\n",
    "print(ins_arr)\n",
    "print(ins_arr == stu_arr)"
   ]
  },
  {
   "cell_type": "markdown",
   "metadata": {
    "deletable": false,
    "editable": false,
    "nbgrader": {
     "grade": false,
     "locked": true,
     "solution": false
    }
   },
   "source": [
    "That didn't do much good. Is there a problem in the test, because it looks like everything matches? The issue with this strategy is the output is truncated because the arrays are huge. We need to figure out where our code outputs the wrong answer so that we can investigate how it gets there. "
   ]
  },
  {
   "cell_type": "code",
   "execution_count": 17,
   "metadata": {
    "deletable": false,
    "editable": false,
    "nbgrader": {
     "grade": false,
     "locked": true,
     "solution": false
    }
   },
   "outputs": [
    {
     "name": "stdout",
     "output_type": "stream",
     "text": [
      "[25, 723, 1995, 5000]\n",
      "[1. 1. 1. 1.]\n",
      "[0. 0. 0. 0.]\n"
     ]
    }
   ],
   "source": [
    "wrong = [i for i, c in enumerate(ins_arr != stu_arr) if c]\n",
    "print(wrong)\n",
    "print(stu_arr[wrong])\n",
    "print(ins_arr[wrong])"
   ]
  },
  {
   "cell_type": "markdown",
   "metadata": {
    "deletable": false,
    "editable": false,
    "nbgrader": {
     "grade": false,
     "locked": true,
     "solution": false
    }
   },
   "source": [
    "The list comprehension stored in wrong is the index of all of the mismatches. With this information, you can investigate the few edge cases that are causing the assertion failure. This technique will often quickly point you towards what isn't being handled correctly in your function. Since these arrays are just dummy examples, we can't go much further. However, this is a good starting point in your debugging process if you're having this type of assertion failure."
   ]
  },
  {
   "cell_type": "markdown",
   "metadata": {
    "deletable": false,
    "editable": false,
    "nbgrader": {
     "grade": false,
     "locked": true,
     "solution": false
    }
   },
   "source": [
    "# Key Takeaways"
   ]
  },
  {
   "cell_type": "markdown",
   "metadata": {
    "deletable": false,
    "editable": false,
    "nbgrader": {
     "grade": false,
     "locked": true,
     "solution": false
    }
   },
   "source": [
    " * If there are issues with failing hidden test cells, look at the **Grading report**. (Details -> View Grading Report)\n",
    "     * This is where the error traceback you need to look at lives.\n",
    "     * Sometimes this requires finding errors above the test cell where variable assignments fail.\n",
    " * Look at the whole error traceback\n",
    " * **Look at the whole error traceback**\n",
    " * Use the traceback to get clues as to why your code is failing. \n",
    "     * Which function call resulted in the error? Focus on functions where you actually wrote some code.\n",
    "     * What type of error is it?\n",
    "     * What attribute is causing the error (shape, column name, index out of bounds, variable name, etc)?\n",
    " * Use print or assert to investigate the source of the error. It is rarely useful to print out entire data frames or arrays, because those usually get truncated.\n",
    " * If there is an assertion error, look for the mismatches. They can usually point you in the right direction."
   ]
  },
  {
   "cell_type": "markdown",
   "metadata": {
    "deletable": false,
    "editable": false,
    "nbgrader": {
     "grade": false,
     "locked": true,
     "solution": false
    }
   },
   "source": [
    "This notebook isn't inended to be a complete guide to debugging. Hopefully these strategies are helpful in completing the notebooks in this course."
   ]
  }
 ],
 "metadata": {
  "kernelspec": {
   "display_name": "Python 3 [3.6]",
   "language": "python",
   "name": "python3"
  },
  "language_info": {
   "codemirror_mode": {
    "name": "ipython",
    "version": 3
   },
   "file_extension": ".py",
   "mimetype": "text/x-python",
   "name": "python",
   "nbconvert_exporter": "python",
   "pygments_lexer": "ipython3",
   "version": "3.6.4"
  }
 },
 "nbformat": 4,
 "nbformat_minor": 4
}
